{"trial_id": "10", "hyperparameters": {"space": [{"class_name": "Int", "config": {"name": "units", "default": null, "conditions": [], "min_value": 32, "max_value": 512, "step": 32, "sampling": "linear"}}, {"class_name": "Float", "config": {"name": "dropout", "default": 0.25, "conditions": [], "min_value": 0.0, "max_value": 0.5, "step": 0.05, "sampling": "linear"}}, {"class_name": "Int", "config": {"name": "units_2", "default": null, "conditions": [], "min_value": 32, "max_value": 512, "step": 32, "sampling": "linear"}}, {"class_name": "Choice", "config": {"name": "activation", "default": "relu", "conditions": [], "values": ["relu", "sigmoid"], "ordered": false}}, {"class_name": "Choice", "config": {"name": "learning_rate", "default": 0.01, "conditions": [], "values": [0.01, 0.001, 0.0001], "ordered": true}}], "values": {"units": 512, "dropout": 0.30000000000000004, "units_2": 128, "activation": "relu", "learning_rate": 0.0001}}, "metrics": {"metrics": {}}, "score": null, "best_step": 0, "status": "FAILED", "message": "Traceback (most recent call last):\n  File \"C:\\Users\\pedr\\AppData\\Local\\Programs\\Python\\Python311\\Lib\\site-packages\\keras_tuner\\src\\engine\\base_tuner.py\", line 270, in _try_run_and_update_trial\n    self._run_and_update_trial(trial, *fit_args, **fit_kwargs)\n  File \"C:\\Users\\pedr\\AppData\\Local\\Programs\\Python\\Python311\\Lib\\site-packages\\keras_tuner\\src\\engine\\base_tuner.py\", line 235, in _run_and_update_trial\n    results = self.run_trial(trial, *fit_args, **fit_kwargs)\n              ^^^^^^^^^^^^^^^^^^^^^^^^^^^^^^^^^^^^^^^^^^^^^^\n  File \"C:\\Users\\pedr\\AppData\\Local\\Programs\\Python\\Python311\\Lib\\site-packages\\keras_tuner\\src\\engine\\tuner.py\", line 314, in run_trial\n    obj_value = self._build_and_fit_model(trial, *args, **copied_kwargs)\n                ^^^^^^^^^^^^^^^^^^^^^^^^^^^^^^^^^^^^^^^^^^^^^^^^^^^^^^^^\n  File \"C:\\Users\\pedr\\AppData\\Local\\Programs\\Python\\Python311\\Lib\\site-packages\\keras_tuner\\src\\engine\\tuner.py\", line 233, in _build_and_fit_model\n    results = self.hypermodel.fit(hp, model, *args, **kwargs)\n              ^^^^^^^^^^^^^^^^^^^^^^^^^^^^^^^^^^^^^^^^^^^^^^^\n  File \"C:\\Users\\pedr\\AppData\\Local\\Programs\\Python\\Python311\\Lib\\site-packages\\keras_tuner\\src\\engine\\hypermodel.py\", line 144, in fit\n    return model.fit(*args, **kwargs)\n           ^^^^^^^^^^^^^^^^^^^^^^^^^^\n  File \"C:\\Users\\pedr\\AppData\\Local\\Programs\\Python\\Python311\\Lib\\site-packages\\keras\\src\\utils\\traceback_utils.py\", line 70, in error_handler\n    raise e.with_traceback(filtered_tb) from None\n  File \"C:\\Users\\pedr\\AppData\\Local\\Temp\\__autograph_generated_filenuwftx29.py\", line 18, in tf__train_function\n    raise\nValueError: in user code:\n\n    File \"C:\\Users\\pedr\\AppData\\Local\\Programs\\Python\\Python311\\Lib\\site-packages\\keras\\src\\engine\\training.py\", line 1377, in train_function  *\n        return step_function(self, iterator)\n    File \"C:\\Users\\pedr\\AppData\\Local\\Programs\\Python\\Python311\\Lib\\site-packages\\keras\\src\\engine\\training.py\", line 1360, in step_function  **\n        outputs = model.distribute_strategy.run(run_step, args=(data,))\n    File \"C:\\Users\\pedr\\AppData\\Local\\Programs\\Python\\Python311\\Lib\\site-packages\\keras\\src\\engine\\training.py\", line 1349, in run_step  **\n        outputs = model.train_step(data)\n    File \"C:\\Users\\pedr\\AppData\\Local\\Programs\\Python\\Python311\\Lib\\site-packages\\keras\\src\\engine\\training.py\", line 1126, in train_step\n        y_pred = self(x, training=True)\n    File \"C:\\Users\\pedr\\AppData\\Local\\Programs\\Python\\Python311\\Lib\\site-packages\\keras\\src\\utils\\traceback_utils.py\", line 70, in error_handler\n        raise e.with_traceback(filtered_tb) from None\n    File \"C:\\Users\\pedr\\AppData\\Local\\Programs\\Python\\Python311\\Lib\\site-packages\\keras\\src\\engine\\input_spec.py\", line 298, in assert_input_compatibility\n        raise ValueError(\n\n    ValueError: Exception encountered when calling layer 'sequential' (type Sequential).\n    \n    Input 0 of layer \"lstm\" is incompatible with the layer: expected shape=(None, None, 3), found shape=(None, 5, 1)\n    \n    Call arguments received by layer 'sequential' (type Sequential):\n      \u2022 inputs=tf.Tensor(shape=(None, 5, 1), dtype=float32)\n      \u2022 training=True\n      \u2022 mask=None\n\n"}